Workbook

Sheet 16-17
A1: number | B1: team | C1: matches | D1: wins | E1: draws | F1: loses | G1: goals | H1: ga | I1: points | J1: xG | K1: xGA | L1: xPTS
A2: 1 | B2: Chelsea | C2: 38 | D2: 30 | E2: 3 | F2: 5 | G2: 85 | H2: 33 | I2: 93 | J2: 61.8 | K2: 28.62 | L2: 75.74
A3: 2 | B3: Tottenham | C3: 38 | D3: 26 | E3: 8 | F3: 4 | G3: 86 | H3: 26 | I3: 86 | J3: 70.07 | K3: 33.78 | L3: 75.37
A4: 3 | B4: Manchester City | C4: 38 | D4: 23 | E4: 9 | F4: 6 | G4: 80 | H4: 39 | I4: 78 | J4: 79.85 | K4: 29.61 | L4: 85.41
A5: 4 | B5: Liverpool | C5: 38 | D5: 22 | E5: 10 | F5: 6 | G5: 78 | H5: 42 | I5: 76 | J5: 66.63 | K5: 37.65 | L5: 69.83
A6: 5 | B6: Arsenal | C6: 38 | D6: 23 | E6: 6 | F6: 9 | G6: 77 | H6: 44 | I6: 75 | J6: 63.58 | K6: 47.07 | L6: 62.12
A7: 6 | B7: Manchester United | C7: 38 | D7: 18 | E7: 15 | F7: 5 | G7: 54 | H7: 29 | I7: 69 | J7: 57.57 | K7: 31.62 | L7: 70.89
A8: 7 | B8: Everton | C8: 38 | D8: 17 | E8: 10 | F8: 11 | G8: 62 | H8: 44 | I8: 61 | J8: 49.63 | K8: 45.78 | L8: 55.78
A9: 8 | B9: Southampton | C9: 38 | D9: 12 | E9: 10 | F9: 16 | G9: 41 | H9: 48 | I9: 46 | J9: 49.98 | K9: 43.08 | L9: 55.69
A10: 9 | B10: Bournemouth | C10: 38 | D10: 12 | E10: 10 | F10: 16 | G10: 55 | H10: 67 | I10: 46 | J10: 50.02 | K10: 62.99 | L10: 43.17
A11: 10 | B11: West Bromwich Albion | C11: 38 | D11: 12 | E11: 9 | F11: 17 | G11: 43 | H11: 51 | I11: 45 | J11: 38.21 | K11: 47.9 | L11: 45.59
A12: 11 | B12: West Ham | C12: 38 | D12: 12 | E12: 9 | F12: 17 | G12: 47 | H12: 64 | I12: 45 | J12: 48.25 | K12: 59.67 | L12: 46.04
A13: 12 | B13: Leicester | C13: 38 | D13: 12 | E13: 8 | F13: 18 | G13: 48 | H13: 63 | I13: 44 | J13: 44.34 | K13: 51.3 | L13: 48.12
... A21: 20 | B21: Sunderland | C21: 38 | D21: 6 | E21: 6 | F21: 26 | G21: 29 | H21: 69 | I21: 24 | J21: 34.22 | K21: 65.66 | L21: 32.24

Sheet 17-18 First 5
A1: number | B1: team | C1: matches | D1: wins | E1: draws | F1: loses | G1: goals | H1: ga | I1: points | J1: xG | K1: xGA | L1: xPTS
A2: 1 | B2: Manchester City | C2: 5 | D2: 4 | E2: 1 | F2: 0 | G2: 16 | H2: 2 | I2: 13 | J2: 11.92 | K2: 2.76 | L2: 12.62
A3: 2 | B3: Manchester United | C3: 5 | D3: 4 | E3: 1 | F3: 0 | G3: 16 | H3: 2 | I3: 13 | J3: 14.04 | K3: 4.16 | L3: 12.73
A4: 3 | B4: Chelsea | C4: 5 | D4: 3 | E4: 1 | F4: 1 | G4: 8 | H4: 5 | I4: 10 | J4: 5.16 | K4: 4.39 | L4: 7.34
A5: 4 | B5: Newcastle United | C5: 5 | D5: 3 | E5: 0 | F5: 2 | G5: 6 | H5: 4 | I5: 9 | J5: 8.06 | K5: 5.33 | L5: 8.72
A6: 5 | B6: Tottenham | C6: 5 | D6: 2 | E6: 2 | F6: 1 | G6: 7 | H6: 3 | I6: 8 | J6: 8.77 | K6: 3.45 | L6: 10.64
A7: 6 | B7: Huddersfield | C7: 5 | D7: 2 | E7: 2 | F7: 1 | G7: 5 | H7: 3 | I7: 8 | J7: 4.56 | K7: 5.95 | L7: 5.56
A8: 7 | B8: Burnley | C8: 5 | D8: 2 | E8: 2 | F8: 1 | G8: 6 | H8: 5 | I8: 8 | J8: 3.37 | K8: 8.28 | L8: 3.55
A9: 8 | B9: Liverpool | C9: 5 | D9: 2 | E9: 2 | F9: 1 | G9: 9 | H9: 9 | I9: 8 | J9: 11.78 | K9: 6.87 | L9: 10.1
A10: 9 | B10: Southampton | C10: 5 | D10: 2 | E10: 2 | F10: 1 | G10: 4 | H10: 4 | I10: 8 | J10: 6.6 | K10: 6.07 | L10: 6.97
A11: 10 | B11: West Bromwich Albion | C11: 5 | D11: 2 | E11: 2 | F11: 1 | G11: 4 | H11: 4 | I11: 8 | J11: 4.36 | K11: 3.4 | L11: 7.74
A12: 11 | B12: Watford | C12: 5 | D12: 2 | E12: 2 | F12: 1 | G12: 7 | H12: 9 | I12: 8 | J12: 6.02 | K12: 8.66 | L12: 5.68
A13: 12 | B13: Arsenal | C13: 5 | D13: 2 | E13: 1 | F13: 2 | G13: 7 | H13: 8 | I13: 7 | J13: 8.34 | K13: 6.96 | L13: 8.72
... A21: 20 | B21: Crystal Palace | C21: 5 | D21: 0 | E21: 0 | F21: 5 | G21: 0 | H21: 8 | I21: 0 | J21: 6.3 | K21: 7.1 | L21: 6.56
A24: number | B24: team | C24: matches | D24: wins | E24: draws | F24: loses | G24: goals | H24: ga | I24: points | J24: xG | K24: xGA | L24: xPTS
A25: 1 | B25: Manchester City | C25: 10 | D25: 9 | E25: 1 | F25: 0 | G25: 35 | H25: 6 | I25: 28 | J25: 29.81 | K25: 6.23 | L25: 25.68
A26: 2 | B26: Manchester United | C26: 10 | D26: 7 | E26: 2 | F26: 1 | G26: 23 | H26: 4 | I26: 23 | J26: 20.57 | K26: 9.49 | L26: 19.61
A27: 3 | B27: Tottenham | C27: 10 | D27: 6 | E27: 2 | F27: 2 | G27: 19 | H27: 7 | I27: 20 | J27: 17.45 | K27: 6.11 | L27: 21.97
A28: 4 | B28: Chelsea | C28: 10 | D28: 6 | E28: 1 | F28: 3 | G28: 18 | H28: 10 | I28: 19 | J28: 11.89 | K28: 9.99 | L28: 15.14
A29: 5 | B29: Arsenal | C29: 10 | D29: 6 | E29: 1 | F29: 3 | G29: 19 | H29: 13 | I29: 19 | J29: 20.44 | K29: 11.39 | L29: 20.07
A30: 6 | B30: Liverpool | C30: 10 | D30: 4 | E30: 4 | F30: 2 | G30: 17 | H30: 16 | I30: 16 | J30: 20.09 | K30: 12.94 | L30: 19.09
A31: 7 | B31: Burnley | C31: 10 | D31: 4 | E31: 4 | F31: 2 | G31: 9 | H31: 9 | I31: 16 | J31: 6 | K31: 14.59 | L31: 8.69
A32: 8 | B32: Watford | C32: 10 | D32: 4 | E32: 3 | F32: 3 | G32: 15 | H32: 18 | I32: 15 | J32: 13.47 | K32: 15.66 | L32: 12.81
A33: 9 | B33: Newcastle United | C33: 10 | D33: 4 | E33: 2 | F33: 4 | G33: 10 | H33: 9 | I33: 14 | J33: 11.45 | K33: 10.79 | L33: 13.64
A34: 10 | B34: Southampton | C34: 10 | D34: 3 | E34: 4 | F34: 3 | G34: 9 | H34: 10 | I34: 13 | J34: 13.11 | K34: 12.78 | L34: 13.6
A35: 11 | B35: Leicester | C35: 10 | D35: 3 | E35: 3 | F35: 4 | G35: 14 | H35: 14 | I35: 12 | J35: 14.23 | K35: 11.76 | L35: 16.68
A36: 12 | B36: Brighton | C36: 10 | D36: 3 | E36: 3 | F36: 4 | G36: 10 | H36: 11 | I36: 12 | J36: 8.06 | K36: 12.71 | L36: 10.54
... A44: 20 | B44: Crystal Palace | C44: 10 | D44: 1 | E44: 1 | F44: 8 | G44: 4 | H44: 21 | I44: 4 | J44: 12.16 | K44: 17.96 | L44: 13.04
A48: number | B48: team | C48: matches | D48: wins | E48: draws | F48: loses | G48: goals | H48: ga | I48: points | J48: xG | K48: xGA | L48: xPTS
A49: 1 | B49: Manchester City | C49: 15 | D49: 14 | E49: 1 | F49: 0 | G49: 46 | H49: 10 | I49: 43 | J49: 41.13 | K49: 9.39 | L49: 38.17
A50: 2 | B50: Manchester United | C50: 15 | D50: 11 | E50: 2 | F50: 2 | G50: 35 | H50: 9 | I50: 35 | J50: 29.12 | K50: 18.52 | L50: 26.72
A51: 3 | B51: Chelsea | C51: 15 | D51: 10 | E51: 2 | F51: 3 | G51: 28 | H51: 12 | I51: 32 | J51: 21.57 | K51: 13.42 | L51: 26.05
A52: 4 | B52: Liverpool | C52: 15 | D52: 8 | E52: 5 | F52: 2 | G52: 33 | H52: 19 | I52: 29 | J52: 30.9 | K52: 17.88 | L52: 30.04
A53: 5 | B53: Arsenal | C53: 15 | D53: 9 | E53: 1 | F53: 5 | G53: 29 | H53: 19 | I53: 28 | J53: 33.5 | K53: 17.08 | L53: 30.86
A54: 6 | B54: Tottenham | C54: 15 | D54: 7 | E54: 4 | F54: 4 | G54: 23 | H54: 13 | I54: 25 | J54: 24.24 | K54: 11.44 | L54: 30.21
A55: 7 | B55: Burnley | C55: 15 | D55: 7 | E55: 4 | F55: 4 | G55: 14 | H55: 12 | I55: 25 | J55: 9.96 | K55: 20.09 | L55: 14.1
A56: 8 | B56: Watford | C56: 15 | D56: 6 | E56: 4 | F56: 5 | G56: 25 | H56: 26 | I56: 22 | J56: 20.47 | K56: 22.95 | L56: 19.05
A57: 9 | B57: Leicester | C57: 15 | D57: 5 | E57: 5 | F57: 5 | G57: 20 | H57: 20 | I57: 20 | J57: 18.72 | K57: 19.46 | L57: 21.58
A58: 10 | B58: Everton | C58: 15 | D58: 5 | E58: 3 | F58: 7 | G58: 19 | H58: 28 | I58: 18 | J58: 16.85 | K58: 22.42 | L58: 18.18
A59: 11 | B59: Southampton | C59: 15 | D59: 4 | E59: 5 | F59: 6 | G59: 15 | H59: 18 | I59: 17 | J59: 19.14 | K59: 17.89 | L59: 21.37
...

Sheet 17-18 First 10
A1: number | B1: team | C1: matches | D1: wins | E1: draws | F1: loses | G1: goals | H1: ga | I1: points | J1: xG | K1: xGA | L1: xPTS
A2: 1 | B2: Manchester City | C2: 10 | D2: 9 | E2: 1 | F2: 0 | G2: 35 | H2: 6 | I2: 28 | J2: 29.81 | K2: 6.23 | L2: 25.68
A3: 2 | B3: Manchester United | C3: 10 | D3: 7 | E3: 2 | F3: 1 | G3: 23 | H3: 4 | I3: 23 | J3: 20.57 | K3: 9.49 | L3: 19.61
A4: 3 | B4: Tottenham | C4: 10 | D4: 6 | E4: 2 | F4: 2 | G4: 19 | H4: 7 | I4: 20 | J4: 17.45 | K4: 6.11 | L4: 21.97
A5: 4 | B5: Chelsea | C5: 10 | D5: 6 | E5: 1 | F5: 3 | G5: 18 | H5: 10 | I5: 19 | J5: 11.89 | K5: 9.99 | L5: 15.14
A6: 5 | B6: Arsenal | C6: 10 | D6: 6 | E6: 1 | F6: 3 | G6: 19 | H6: 13 | I6: 19 | J6: 20.44 | K6: 11.39 | L6: 20.07
A7: 6 | B7: Liverpool | C7: 10 | D7: 4 | E7: 4 | F7: 2 | G7: 17 | H7: 16 | I7: 16 | J7: 20.09 | K7: 12.94 | L7: 19.09
A8: 7 | B8: Burnley | C8: 10 | D8: 4 | E8: 4 | F8: 2 | G8: 9 | H8: 9 | I8: 16 | J8: 6 | K8: 14.59 | L8: 8.69
A9: 8 | B9: Watford | C9: 10 | D9: 4 | E9: 3 | F9: 3 | G9: 15 | H9: 18 | I9: 15 | J9: 13.47 | K9: 15.66 | L9: 12.81
A10: 9 | B10: Newcastle United | C10: 10 | D10: 4 | E10: 2 | F10: 4 | G10: 10 | H10: 9 | I10: 14 | J10: 11.45 | K10: 10.79 | L10: 13.64
A11: 10 | B11: Southampton | C11: 10 | D11: 3 | E11: 4 | F11: 3 | G11: 9 | H11: 10 | I11: 13 | J11: 13.11 | K11: 12.78 | L11: 13.6
A12: 11 | B12: Leicester | C12: 10 | D12: 3 | E12: 3 | F12: 4 | G12: 14 | H12: 14 | I12: 12 | J12: 14.23 | K12: 11.76 | L12: 16.68
A13: 12 | B13: Brighton | C13: 10 | D13: 3 | E13: 3 | F13: 4 | G13: 10 | H13: 11 | I13: 12 | J13: 8.06 | K13: 12.71 | L13: 10.54
... A21: 20 | B21: Crystal Palace | C21: 10 | D21: 1 | E21: 1 | F21: 8 | G21: 4 | H21: 21 | I21: 4 | J21: 12.16 | K21: 17.96 | L21: 13.04

Sheet 17-18 First 15
B1: team | C1: matches | D1: wins | E1: draws | F1: loses | G1: goals | H1: ga | I1: points | J1: xG | K1: xGA | L1: xPTS
A2: 1 | B2: Manchester City | C2: 15 | D2: 14 | E2: 1 | F2: 0 | G2: 46 | H2: 10 | I2: 43 | J2: 41.13 | K2: 9.39 | L2: 38.17
A3: 2 | B3: Manchester United | C3: 15 | D3: 11 | E3: 2 | F3: 2 | G3: 35 | H3: 9 | I3: 35 | J3: 29.12 | K3: 18.52 | L3: 26.72
A4: 3 | B4: Chelsea | C4: 15 | D4: 10 | E4: 2 | F4: 3 | G4: 28 | H4: 12 | I4: 32 | J4: 21.57 | K4: 13.42 | L4: 26.05
A5: 4 | B5: Liverpool | C5: 15 | D5: 8 | E5: 5 | F5: 2 | G5: 33 | H5: 19 | I5: 29 | J5: 30.9 | K5: 17.88 | L5: 30.04
A6: 5 | B6: Arsenal | C6: 15 | D6: 9 | E6: 1 | F6: 5 | G6: 29 | H6: 19 | I6: 28 | J6: 33.5 | K6: 17.08 | L6: 30.86
A7: 6 | B7: Tottenham | C7: 15 | D7: 7 | E7: 4 | F7: 4 | G7: 23 | H7: 13 | I7: 25 | J7: 24.24 | K7: 11.44 | L7: 30.21
A8: 7 | B8: Burnley | C8: 15 | D8: 7 | E8: 4 | F8: 4 | G8: 14 | H8: 12 | I8: 25 | J8: 9.96 | K8: 20.09 | L8: 14.1
A9: 8 | B9: Watford | C9: 15 | D9: 6 | E9: 4 | F9: 5 | G9: 25 | H9: 26 | I9: 22 | J9: 20.47 | K9: 22.95 | L9: 19.05
A10: 9 | B10: Leicester | C10: 15 | D10: 5 | E10: 5 | F10: 5 | G10: 20 | H10: 20 | I10: 20 | J10: 18.72 | K10: 19.46 | L10: 21.58
A11: 10 | B11: Everton | C11: 15 | D11: 5 | E11: 3 | F11: 7 | G11: 19 | H11: 28 | I11: 18 | J11: 16.85 | K11: 22.42 | L11: 18.18
A12: 11 | B12: Southampton | C12: 15 | D12: 4 | E12: 5 | F12: 6 | G12: 15 | H12: 18 | I12: 17 | J12: 19.14 | K12: 17.89 | L12: 21.37
A13: 12 | B13: Brighton | C13: 15 | D13: 4 | E13: 5 | F13: 6 | G13: 14 | H13: 19 | I13: 17 | J13: 12.13 | K13: 19.02 | L13: 15.1
... A21: 20 | B21: Swansea | C21: 15 | D21: 2 | E21: 3 | F21: 10 | G21: 8 | H21: 18 | I21: 9 | J21: 10.97 | K21: 21.8 | L21: 13.89

Sheet 17-18 First 20
A1: number | B1: team | C1: matches | D1: wins | E1: draws | F1: loses | G1: goals | H1: ga | I1: points | J1: xG | K1: xGA | L1: xPTS
A2: 1 | B2: Manchester City | C2: 20 | D2: 19 | E2: 1 | F2: 0 | G2: 61 | H2: 12 | I2: 58 | J2: 54.37 | K2: 12.11 | L2: 50.87
A3: 2 | B3: Manchester United | C3: 20 | D3: 13 | E3: 4 | F3: 3 | G3: 43 | H3: 16 | I3: 43 | J3: 36.66 | K3: 24.79 | L3: 34.44
A4: 3 | B4: Chelsea | C4: 20 | D4: 13 | E4: 3 | F4: 4 | G4: 34 | H4: 14 | I4: 42 | J4: 29.94 | K4: 15.69 | L4: 37.63
A5: 4 | B5: Liverpool | C5: 20 | D5: 10 | E5: 8 | F5: 2 | G5: 46 | H5: 23 | I5: 38 | J5: 43.3 | K5: 21.17 | L5: 42.57
A6: 5 | B6: Tottenham | C6: 20 | D6: 11 | E6: 4 | F6: 5 | G6: 39 | H6: 20 | I6: 37 | J6: 36.71 | K6: 17.41 | L6: 41.42
A7: 6 | B7: Arsenal | C7: 20 | D7: 11 | E7: 4 | F7: 5 | G7: 37 | H7: 25 | I7: 37 | J7: 40.12 | K7: 22.19 | L7: 38.69
A8: 7 | B8: Burnley | C8: 20 | D8: 9 | E8: 6 | F8: 5 | G8: 18 | H8: 17 | I8: 33 | J8: 13.08 | K8: 28.44 | L8: 17.58
A9: 8 | B9: Leicester | C9: 20 | D9: 7 | E9: 6 | F9: 7 | G9: 30 | H9: 30 | I9: 27 | J9: 25.28 | K9: 27.39 | L9: 27.37
A10: 9 | B10: Everton | C10: 20 | D10: 7 | E10: 6 | F10: 7 | G10: 24 | H10: 30 | I10: 27 | J10: 21.82 | K10: 28.69 | L10: 24.36
A11: 10 | B11: Watford | C11: 20 | D11: 7 | E11: 4 | F11: 9 | G11: 29 | H11: 35 | I11: 25 | J11: 26.01 | K11: 30.99 | L11: 24.9
A12: 11 | B12: Huddersfield | C12: 20 | D12: 6 | E12: 5 | F12: 9 | G12: 18 | H12: 32 | I12: 23 | J12: 19.27 | K12: 27.89 | L12: 21.19
A13: 12 | B13: Brighton | C13: 20 | D13: 5 | E13: 6 | F13: 9 | G13: 15 | H13: 25 | I13: 21 | J13: 16.06 | K13: 28.37 | L13: 18.71
... A21: 20 | B21: Swansea | C21: 20 | D21: 3 | E21: 4 | F21: 13 | G21: 11 | H21: 31 | I21: 13 | J21: 14.16 | K21: 31.96 | L21: 17.07

Sheet Summary
A1: Team | B1: 16-17 GD/Game | C1: 17-18 GD/Game 5 | D1: 17-18 GD/Game 10 | E1: 17-18 GD/Game 15 | F1: 17-18 GD/Game 20 | G1: Final Rank | H1: Rank 16-17 | I1: Rank 5 | J1: Rank 10 | K1: Rank 15 | L1: Rank 20 | M1: Error 16-17 | N1: Error 5 | O1: Error 10 | P1: Error 15 | Q1: Error 20 | R1: Sq Error 16-17 | S1: Sq Error 5 | T1: Sq Error 10 | U1: Sq Error 15 | V1: Sq Error 20 | X1: Games | Y1: Current MAE | Z1: Current RMSE | AA1: Last Season MAE | AB1: Last Season RMSE
A2: Manchester City | B2: =IFERROR((VLOOKUP($A2,'16-17'!$B:$L,6,FALSE)-VLOOKUP($A2,'16-17'!$B:$L,7,FALSE))/VLOOKUP($A2,'16-17'!$B:$L,2,FALSE),"") -> 1.0789474 | C2: =IFERROR((VLOOKUP($A2,'17-18 First 5'!$B:$L,6,FALSE)-VLOOKUP($A2,'17-18 First 5'!$B:$L,7,FALSE))/VLOOKUP($A2,'17-18 First 5'!$B:$L,2,FALSE),"") -> 2.8 | D2: =IFERROR((VLOOKUP($A2,'17-18 First 10'!$B:$L,6,FALSE)-VLOOKUP($A2,'17-18 First 10'!$B:$L,7,FALSE))/VLOOKUP($A2,'17-18 First 10'!$B:$L,2,FALSE),"") -> 2.9 | E2: =IFERROR((VLOOKUP($A2,'17-18 First 15'!$B:$L,6,FALSE)-VLOOKUP($A2,'17-18 First 15'!$B:$L,7,FALSE))/VLOOKUP($A2,'17-18 First 15'!$B:$L,2,FALSE),"") -> 2.4 | F2: =IFERROR((VLOOKUP($A2,'17-18 First 20'!$B:$L,6,FALSE)-VLOOKUP($A2,'17-18 First 20'!$B:$L,7,FALSE))/VLOOKUP($A2,'17-18 First 20'!$B:$L,2,FALSE),"") -> 2.45 | G2: 1 | H2: =IFERROR(RANK(B2,$B$2:$B$21,0),"") -> 3 | I2: =IFERROR(RANK(C2,$C$2:$C$21,0),"") -> 1 | J2: =IFERROR(RANK(D2,$D$2:$D$21,0),"") -> 1 | K2: =IFERROR(RANK(E2,$E$2:$E$21,0),"") -> 1 | L2: =IFERROR(RANK(F2,$F$2:$F$21,0),"") -> 1 | M2: =IFERROR(ABS(H2-$G2),"") -> 2 | N2: =IFERROR(ABS(I2-$G2),"") -> 0 | O2: =IFERROR(ABS(J2-$G2),"") -> 0 | P2: =IFERROR(ABS(K2-$G2),"") -> 0 | Q2: =IFERROR(ABS(L2-$G2),"") -> 0 | R2: =IFERROR(M2^2,"") -> 4 | S2: =IFERROR(N2^2,"") -> 0 | T2: =IFERROR(O2^2,"") -> 0 | U2: =IFERROR(P2^2,"") -> 0 | V2: =IFERROR(Q2^2,"") -> 0 | X2: 5 | Y2: =AVERAGE(N$2:N$21) -> 4.6 | Z2: =SQRT(AVERAGE(S$2:S$21)) -> 6.041523 | AA2: =AVERAGE($M$2:$M$21) -> 3.4705882 | AB2: =SQRT(AVERAGE($R$2:$R$21)) -> 4.6336366
A3: Manchester United | B3: =IFERROR((VLOOKUP($A3,'16-17'!$B:$L,6,FALSE)-VLOOKUP($A3,'16-17'!$B:$L,7,FALSE))/VLOOKUP($A3,'16-17'!$B:$L,2,FALSE),"") -> 0.65789474 | C3: =IFERROR((VLOOKUP($A3,'17-18 First 5'!$B:$L,6,FALSE)-VLOOKUP($A3,'17-18 First 5'!$B:$L,7,FALSE))/VLOOKUP($A3,'17-18 First 5'!$B:$L,2,FALSE),"") -> 2.8 | D3: =IFERROR((VLOOKUP($A3,'17-18 First 10'!$B:$L,6,FALSE)-VLOOKUP($A3,'17-18 First 10'!$B:$L,7,FALSE))/VLOOKUP($A3,'17-18 First 10'!$B:$L,2,FALSE),"") -> 1.9 | E3: =IFERROR((VLOOKUP($A3,'17-18 First 15'!$B:$L,6,FALSE)-VLOOKUP($A3,'17-18 First 15'!$B:$L,7,FALSE))/VLOOKUP($A3,'17-18 First 15'!$B:$L,2,FALSE),"") -> 1.7333333 | F3: =IFERROR((VLOOKUP($A3,'17-18 First 20'!$B:$L,6,FALSE)-VLOOKUP($A3,'17-18 First 20'!$B:$L,7,FALSE))/VLOOKUP($A3,'17-18 First 20'!$B:$L,2,FALSE),"") -> 1.35 | G3: 2 | H3: =IFERROR(RANK(B3,$B$2:$B$21,0),"") -> 6 | I3: =IFERROR(RANK(C3,$C$2:$C$21,0),"") -> 1 | J3: =IFERROR(RANK(D3,$D$2:$D$21,0),"") -> 2 | K3: =IFERROR(RANK(E3,$E$2:$E$21,0),"") -> 2 | L3: =IFERROR(RANK(F3,$F$2:$F$21,0),"") -> 2 | M3: =IFERROR(ABS(H3-$G3),"") -> 4 | N3: =IFERROR(ABS(I3-$G3),"") -> 1 | O3: =IFERROR(ABS(J3-$G3),"") -> 0 | P3: =IFERROR(ABS(K3-$G3),"") -> 0 | Q3: =IFERROR(ABS(L3-$G3),"") -> 0 | R3: =IFERROR(M3^2,"") -> 16 | S3: =IFERROR(N3^2,"") -> 1 | T3: =IFERROR(O3^2,"") -> 0 | U3: =IFERROR(P3^2,"") -> 0 | V3: =IFERROR(Q3^2,"") -> 0 | X3: 10 | Y3: =AVERAGE(O$2:O$21) -> 3.3 | Z3: =SQRT(AVERAGE(T$2:T$21)) -> 4.5055521 | AA3: =AVERAGE($M$2:$M$21) -> 3.4705882 | AB3: =SQRT(AVERAGE($R$2:$R$21)) -> 4.6336366
A4: Chelsea | B4: =IFERROR((VLOOKUP($A4,'16-17'!$B:$L,6,FALSE)-VLOOKUP($A4,'16-17'!$B:$L,7,FALSE))/VLOOKUP($A4,'16-17'!$B:$L,2,FALSE),"") -> 1.3684211 | C4: =IFERROR((VLOOKUP($A4,'17-18 First 5'!$B:$L,6,FALSE)-VLOOKUP($A4,'17-18 First 5'!$B:$L,7,FALSE))/VLOOKUP($A4,'17-18 First 5'!$B:$L,2,FALSE),"") -> 0.6 | D4: =IFERROR((VLOOKUP($A4,'17-18 First 10'!$B:$L,6,FALSE)-VLOOKUP($A4,'17-18 First 10'!$B:$L,7,FALSE))/VLOOKUP($A4,'17-18 First 10'!$B:$L,2,FALSE),"") -> 0.8 | E4: =IFERROR((VLOOKUP($A4,'17-18 First 15'!$B:$L,6,FALSE)-VLOOKUP($A4,'17-18 First 15'!$B:$L,7,FALSE))/VLOOKUP($A4,'17-18 First 15'!$B:$L,2,FALSE),"") -> 1.0666667 | F4: =IFERROR((VLOOKUP($A4,'17-18 First 20'!$B:$L,6,FALSE)-VLOOKUP($A4,'17-18 First 20'!$B:$L,7,FALSE))/VLOOKUP($A4,'17-18 First 20'!$B:$L,2,FALSE),"") -> 1 | G4: 5 | H4: =IFERROR(RANK(B4,$B$2:$B$21,0),"") -> 2 | I4: =IFERROR(RANK(C4,$C$2:$C$21,0),"") -> 4 | J4: =IFERROR(RANK(D4,$D$2:$D$21,0),"") -> 4 | K4: =IFERROR(RANK(E4,$E$2:$E$21,0),"") -> 3 | L4: =IFERROR(RANK(F4,$F$2:$F$21,0),"") -> 4 | M4: =IFERROR(ABS(H4-$G4),"") -> 3 | N4: =IFERROR(ABS(I4-$G4),"") -> 1 | O4: =IFERROR(ABS(J4-$G4),"") -> 1 | P4: =IFERROR(ABS(K4-$G4),"") -> 2 | Q4: =IFERROR(ABS(L4-$G4),"") -> 1 | R4: =IFERROR(M4^2,"") -> 9 | S4: =IFERROR(N4^2,"") -> 1 | T4: =IFERROR(O4^2,"") -> 1 | U4: =IFERROR(P4^2,"") -> 4 | V4: =IFERROR(Q4^2,"") -> 1 | X4: 15 | Y4: =AVERAGE(P$2:P$21) -> 2.85 | Z4: =SQRT(AVERAGE(U$2:U$21)) -> 3.7749172 | AA4: =AVERAGE($M$2:$M$21) -> 3.4705882 | AB4: =SQRT(AVERAGE($R$2:$R$21)) -> 4.6336366
A5: Liverpool | B5: =IFERROR((VLOOKUP($A5,'16-17'!$B:$L,6,FALSE)-VLOOKUP($A5,'16-17'!$B:$L,7,FALSE))/VLOOKUP($A5,'16-17'!$B:$L,2,FALSE),"") -> 0.94736842 | C5: =IFERROR((VLOOKUP($A5,'17-18 First 5'!$B:$L,6,FALSE)-VLOOKUP($A5,'17-18 First 5'!$B:$L,7,FALSE))/VLOOKUP($A5,'17-18 First 5'!$B:$L,2,FALSE),"") -> 0 | D5: =IFERROR((VLOOKUP($A5,'17-18 First 10'!$B:$L,6,FALSE)-VLOOKUP($A5,'17-18 First 10'!$B:$L,7,FALSE))/VLOOKUP($A5,'17-18 First 10'!$B:$L,2,FALSE),"") -> 0.1 | E5: =IFERROR((VLOOKUP($A5,'17-18 First 15'!$B:$L,6,FALSE)-VLOOKUP($A5,'17-18 First 15'!$B:$L,7,FALSE))/VLOOKUP($A5,'17-18 First 15'!$B:$L,2,FALSE),"") -> 0.93333333 | F5: =IFERROR((VLOOKUP($A5,'17-18 First 20'!$B:$L,6,FALSE)-VLOOKUP($A5,'17-18 First 20'!$B:$L,7,FALSE))/VLOOKUP($A5,'17-18 First 20'!$B:$L,2,FALSE),"") -> 1.15 | G5: 4 | H5: =IFERROR(RANK(B5,$B$2:$B$21,0),"") -> 4 | I5: =IFERROR(RANK(C5,$C$2:$C$21,0),"") -> 8 | J5: =IFERROR(RANK(D5,$D$2:$D$21,0),"") -> 6 | K5: =IFERROR(RANK(E5,$E$2:$E$21,0),"") -> 4 | L5: =IFERROR(RANK(F5,$F$2:$F$21,0),"") -> 3 | M5: =IFERROR(ABS(H5-$G5),"") -> 0 | N5: =IFERROR(ABS(I5-$G5),"") -> 4 | O5: =IFERROR(ABS(J5-$G5),"") -> 2 | P5: =IFERROR(ABS(K5-$G5),"") -> 0 | Q5: =IFERROR(ABS(L5-$G5),"") -> 1 | R5: =IFERROR(M5^2,"") -> 0 | S5: =IFERROR(N5^2,"") -> 16 | T5: =IFERROR(O5^2,"") -> 4 | U5: =IFERROR(P5^2,"") -> 0 | V5: =IFERROR(Q5^2,"") -> 1 | X5: 20 | Y5: =AVERAGE(Q$2:Q$21) -> 2.2 | Z5: =SQRT(AVERAGE(V$2:V$21)) -> 3.0659419 | AA5: =AVERAGE($M$2:$M$21) -> 3.4705882 | AB5: =SQRT(AVERAGE($R$2:$R$21)) -> 4.6336366
A6: Tottenham | B6: =IFERROR((VLOOKUP($A6,'16-17'!$B:$L,6,FALSE)-VLOOKUP($A6,'16-17'!$B:$L,7,FALSE))/VLOOKUP($A6,'16-17'!$B:$L,2,FALSE),"") -> 1.5789474 | C6: =IFERROR((VLOOKUP($A6,'17-18 First 5'!$B:$L,6,FALSE)-VLOOKUP($A6,'17-18 First 5'!$B:$L,7,FALSE))/VLOOKUP($A6,'17-18 First 5'!$B:$L,2,FALSE),"") -> 0.8 | D6: =IFERROR((VLOOKUP($A6,'17-18 First 10'!$B:$L,6,FALSE)-VLOOKUP($A6,'17-18 First 10'!$B:$L,7,FALSE))/VLOOKUP($A6,'17-18 First 10'!$B:$L,2,FALSE),"") -> 1.2 | E6: =IFERROR((VLOOKUP($A6,'17-18 First 15'!$B:$L,6,FALSE)-VLOOKUP($A6,'17-18 First 15'!$B:$L,7,FALSE))/VLOOKUP($A6,'17-18 First 15'!$B:$L,2,FALSE),"") -> 0.66666667 | F6: =IFERROR((VLOOKUP($A6,'17-18 First 20'!$B:$L,6,FALSE)-VLOOKUP($A6,'17-18 First 20'!$B:$L,7,FALSE))/VLOOKUP($A6,'17-18 First 20'!$B:$L,2,FALSE),"") -> 0.95 | G6: 3 | H6: =IFERROR(RANK(B6,$B$2:$B$21,0),"") -> 1 | I6: =IFERROR(RANK(C6,$C$2:$C$21,0),"") -> 3 | J6: =IFERROR(RANK(D6,$D$2:$D$21,0),"") -> 3 | K6: =IFERROR(RANK(E6,$E$2:$E$21,0),"") -> 5 | L6: =IFERROR(RANK(F6,$F$2:$F$21,0),"") -> 5 | M6: =IFERROR(ABS(H6-$G6),"") -> 2 | N6: =IFERROR(ABS(I6-$G6),"") -> 0 | O6: =IFERROR(ABS(J6-$G6),"") -> 0 | P6: =IFERROR(ABS(K6-$G6),"") -> 2 | Q6: =IFERROR(ABS(L6-$G6),"") -> 2 | R6: =IFERROR(M6^2,"") -> 4 | S6: =IFERROR(N6^2,"") -> 0 | T6: =IFERROR(O6^2,"") -> 0 | U6: =IFERROR(P6^2,"") -> 4 | V6: =IFERROR(Q6^2,"") -> 4
A7: Arsenal | B7: =IFERROR((VLOOKUP($A7,'16-17'!$B:$L,6,FALSE)-VLOOKUP($A7,'16-17'!$B:$L,7,FALSE))/VLOOKUP($A7,'16-17'!$B:$L,2,FALSE),"") -> 0.86842105 | C7: =IFERROR((VLOOKUP($A7,'17-18 First 5'!$B:$L,6,FALSE)-VLOOKUP($A7,'17-18 First 5'!$B:$L,7,FALSE))/VLOOKUP($A7,'17-18 First 5'!$B:$L,2,FALSE),"") -> -0.2 | D7: =IFERROR((VLOOKUP($A7,'17-18 First 10'!$B:$L,6,FALSE)-VLOOKUP($A7,'17-18 First 10'!$B:$L,7,FALSE))/VLOOKUP($A7,'17-18 First 10'!$B:$L,2,FALSE),"") -> 0.6 | E7: =IFERROR((VLOOKUP($A7,'17-18 First 15'!$B:$L,6,FALSE)-VLOOKUP($A7,'17-18 First 15'!$B:$L,7,FALSE))/VLOOKUP($A7,'17-18 First 15'!$B:$L,2,FALSE),"") -> 0.66666667 | F7: =IFERROR((VLOOKUP($A7,'17-18 First 20'!$B:$L,6,FALSE)-VLOOKUP($A7,'17-18 First 20'!$B:$L,7,FALSE))/VLOOKUP($A7,'17-18 First 20'!$B:$L,2,FALSE),"") -> 0.6 | G7: 6 | H7: =IFERROR(RANK(B7,$B$2:$B$21,0),"") -> 5 | I7: =IFERROR(RANK(C7,$C$2:$C$21,0),"") -> 11 | J7: =IFERROR(RANK(D7,$D$2:$D$21,0),"") -> 5 | K7: =IFERROR(RANK(E7,$E$2:$E$21,0),"") -> 5 | L7: =IFERROR(RANK(F7,$F$2:$F$21,0),"") -> 6 | M7: =IFERROR(ABS(H7-$G7),"") -> 1 | N7: =IFERROR(ABS(I7-$G7),"") -> 5 | O7: =IFERROR(ABS(J7-$G7),"") -> 1 | P7: =IFERROR(ABS(K7-$G7),"") -> 1 | Q7: =IFERROR(ABS(L7-$G7),"") -> 0 | R7: =IFERROR(M7^2,"") -> 1 | S7: =IFERROR(N7^2,"") -> 25 | T7: =IFERROR(O7^2,"") -> 1 | U7: =IFERROR(P7^2,"") -> 1 | V7: =IFERROR(Q7^2,"") -> 0
A8: Burnley | B8: =IFERROR((VLOOKUP($A8,'16-17'!$B:$L,6,FALSE)-VLOOKUP($A8,'16-17'!$B:$L,7,FALSE))/VLOOKUP($A8,'16-17'!$B:$L,2,FALSE),"") -> -0.42105263 | C8: =IFERROR((VLOOKUP($A8,'17-18 First 5'!$B:$L,6,FALSE)-VLOOKUP($A8,'17-18 First 5'!$B:$L,7,FALSE))/VLOOKUP($A8,'17-18 First 5'!$B:$L,2,FALSE),"") -> 0.2 | D8: =IFERROR((VLOOKUP($A8,'17-18 First 10'!$B:$L,6,FALSE)-VLOOKUP($A8,'17-18 First 10'!$B:$L,7,FALSE))/VLOOKUP($A8,'17-18 First 10'!$B:$L,2,FALSE),"") -> 0 | E8: =IFERROR((VLOOKUP($A8,'17-18 First 15'!$B:$L,6,FALSE)-VLOOKUP($A8,'17-18 First 15'!$B:$L,7,FALSE))/VLOOKUP($A8,'17-18 First 15'!$B:$L,2,FALSE),"") -> 0.13333333 | F8: =IFERROR((VLOOKUP($A8,'17-18 First 20'!$B:$L,6,FALSE)-VLOOKUP($A8,'17-18 First 20'!$B:$L,7,FALSE))/VLOOKUP($A8,'17-18 First 20'!$B:$L,2,FALSE),"") -> 0.05 | G8: 7 | H8: =IFERROR(RANK(B8,$B$2:$B$21,0),"") -> 14 | I8: =IFERROR(RANK(C8,$C$2:$C$21,0),"") -> 7 | J8: =IFERROR(RANK(D8,$D$2:$D$21,0),"") -> 8 | K8: =IFERROR(RANK(E8,$E$2:$E$21,0),"") -> 7 | L8: =IFERROR(RANK(F8,$F$2:$F$21,0),"") -> 7 | M8: =IFERROR(ABS(H8-$G8),"") -> 7 | N8: =IFERROR(ABS(I8-$G8),"") -> 0 | O8: =IFERROR(ABS(J8-$G8),"") -> 1 | P8: =IFERROR(ABS(K8-$G8),"") -> 0 | Q8: =IFERROR(ABS(L8-$G8),"") -> 0 | R8: =IFERROR(M8^2,"") -> 49 | S8: =IFERROR(N8^2,"") -> 0 | T8: =IFERROR(O8^2,"") -> 1 | U8: =IFERROR(P8^2,"") -> 0 | V8: =IFERROR(Q8^2,"") -> 0
A9: Leicester | B9: =IFERROR((VLOOKUP($A9,'16-17'!$B:$L,6,FALSE)-VLOOKUP($A9,'16-17'!$B:$L,7,FALSE))/VLOOKUP($A9,'16-17'!$B:$L,2,FALSE),"") -> -0.39473684 | C9: =IFERROR((VLOOKUP($A9,'17-18 First 5'!$B:$L,6,FALSE)-VLOOKUP($A9,'17-18 First 5'!$B:$L,7,FALSE))/VLOOKUP($A9,'17-18 First 5'!$B:$L,2,FALSE),"") -> -0.4 | D9: =IFERROR((VLOOKUP($A9,'17-18 First 10'!$B:$L,6,FALSE)-VLOOKUP($A9,'17-18 First 10'!$B:$L,7,FALSE))/VLOOKUP($A9,'17-18 First 10'!$B:$L,2,FALSE),"") -> 0 | E9: =IFERROR((VLOOKUP($A9,'17-18 First 15'!$B:$L,6,FALSE)-VLOOKUP($A9,'17-18 First 15'!$B:$L,7,FALSE))/VLOOKUP($A9,'17-18 First 15'!$B:$L,2,FALSE),"") -> 0 | F9: =IFERROR((VLOOKUP($A9,'17-18 First 20'!$B:$L,6,FALSE)-VLOOKUP($A9,'17-18 First 20'!$B:$L,7,FALSE))/VLOOKUP($A9,'17-18 First 20'!$B:$L,2,FALSE),"") -> 0 | G9: 9 | H9: =IFERROR(RANK(B9,$B$2:$B$21,0),"") -> 12 | I9: =IFERROR(RANK(C9,$C$2:$C$21,0),"") -> 13 | J9: =IFERROR(RANK(D9,$D$2:$D$21,0),"") -> 8 | K9: =IFERROR(RANK(E9,$E$2:$E$21,0),"") -> 8 | L9: =IFERROR(RANK(F9,$F$2:$F$21,0),"") -> 8 | M9: =IFERROR(ABS(H9-$G9),"") -> 3 | N9: =IFERROR(ABS(I9-$G9),"") -> 4 | O9: =IFERROR(ABS(J9-$G9),"") -> 1 | P9: =IFERROR(ABS(K9-$G9),"") -> 1 | Q9: =IFERROR(ABS(L9-$G9),"") -> 1 | R9: =IFERROR(M9^2,"") -> 9 | S9: =IFERROR(N9^2,"") -> 16 | T9: =IFERROR(O9^2,"") -> 1 | U9: =IFERROR(P9^2,"") -> 1 | V9: =IFERROR(Q9^2,"") -> 1
A10: Everton | B10: =IFERROR((VLOOKUP($A10,'16-17'!$B:$L,6,FALSE)-VLOOKUP($A10,'16-17'!$B:$L,7,FALSE))/VLOOKUP($A10,'16-17'!$B:$L,2,FALSE),"") -> 0.47368421 | C10: =IFERROR((VLOOKUP($A10,'17-18 First 5'!$B:$L,6,FALSE)-VLOOKUP($A10,'17-18 First 5'!$B:$L,7,FALSE))/VLOOKUP($A10,'17-18 First 5'!$B:$L,2,FALSE),"") -> -1.6 | D10: =IFERROR((VLOOKUP($A10,'17-18 First 10'!$B:$L,6,FALSE)-VLOOKUP($A10,'17-18 First 10'!$B:$L,7,FALSE))/VLOOKUP($A10,'17-18 First 10'!$B:$L,2,FALSE),"") -> -1.3 | E10: =IFERROR((VLOOKUP($A10,'17-18 First 15'!$B:$L,6,FALSE)-VLOOKUP($A10,'17-18 First 15'!$B:$L,7,FALSE))/VLOOKUP($A10,'17-18 First 15'!$B:$L,2,FALSE),"") -> -0.6 | F10: =IFERROR((VLOOKUP($A10,'17-18 First 20'!$B:$L,6,FALSE)-VLOOKUP($A10,'17-18 First 20'!$B:$L,7,FALSE))/VLOOKUP($A10,'17-18 First 20'!$B:$L,2,FALSE),"") -> -0.3 | G10: 8 | H10: =IFERROR(RANK(B10,$B$2:$B$21,0),"") -> 7 | I10: =IFERROR(RANK(C10,$C$2:$C$21,0),"") -> 19 | J10: =IFERROR(RANK(D10,$D$2:$D$21,0),"") -> 19 | K10: =IFERROR(RANK(E10,$E$2:$E$21,0),"") -> 14 | L10: =IFERROR(RANK(F10,$F$2:$F$21,0),"") -> 9 | M10: =IFERROR(ABS(H10-$G10),"") -> 1 | N10: =IFERROR(ABS(I10-$G10),"") -> 11 | O10: =IFERROR(ABS(J10-$G10),"") -> 11 | P10: =IFERROR(ABS(K10-$G10),"") -> 6 | Q10: =IFERROR(ABS(L10-$G10),"") -> 1 | R10: =IFERROR(M10^2,"") -> 1 | S10: =IFERROR(N10^2,"") -> 121 | T10: =IFERROR(O10^2,"") -> 121 | U10: =IFERROR(P10^2,"") -> 36 | V10: =IFERROR(Q10^2,"") -> 1
A11: Watford | B11: =IFERROR((VLOOKUP($A11,'16-17'!$B:$L,6,FALSE)-VLOOKUP($A11,'16-17'!$B:$L,7,FALSE))/VLOOKUP($A11,'16-17'!$B:$L,2,FALSE),"") -> -0.73684211 | C11: =IFERROR((VLOOKUP($A11,'17-18 First 5'!$B:$L,6,FALSE)-VLOOKUP($A11,'17-18 First 5'!$B:$L,7,FALSE))/VLOOKUP($A11,'17-18 First 5'!$B:$L,2,FALSE),"") -> -0.4 | D11: =IFERROR((VLOOKUP($A11,'17-18 First 10'!$B:$L,6,FALSE)-VLOOKUP($A11,'17-18 First 10'!$B:$L,7,FALSE))/VLOOKUP($A11,'17-18 First 10'!$B:$L,2,FALSE),"") -> -0.3 | E11: =IFERROR((VLOOKUP($A11,'17-18 First 15'!$B:$L,6,FALSE)-VLOOKUP($A11,'17-18 First 15'!$B:$L,7,FALSE))/VLOOKUP($A11,'17-18 First 15'!$B:$L,2,FALSE),"") -> -0.066666667 | F11: =IFERROR((VLOOKUP($A11,'17-18 First 20'!$B:$L,6,FALSE)-VLOOKUP($A11,'17-18 First 20'!$B:$L,7,FALSE))/VLOOKUP($A11,'17-18 First 20'!$B:$L,2,FALSE),"") -> -0.3 | G11: 14 | H11: =IFERROR(RANK(B11,$B$2:$B$21,0),"") -> 17 | I11: =IFERROR(RANK(C11,$C$2:$C$21,0),"") -> 13 | J11: =IFERROR(RANK(D11,$D$2:$D$21,0),"") -> 12 | K11: =IFERROR(RANK(E11,$E$2:$E$21,0),"") -> 9 | L11: =IFERROR(RANK(F11,$F$2:$F$21,0),"") -> 9 | M11: =IFERROR(ABS(H11-$G11),"") -> 3 | N11: =IFERROR(ABS(I11-$G11),"") -> 1 | O11: =IFERROR(ABS(J11-$G11),"") -> 2 | P11: =IFERROR(ABS(K11-$G11),"") -> 5 | Q11: =IFERROR(ABS(L11-$G11),"") -> 5 | R11: =IFERROR(M11^2,"") -> 9 | S11: =IFERROR(N11^2,"") -> 1 | T11: =IFERROR(O11^2,"") -> 4 | U11: =IFERROR(P11^2,"") -> 25 | V11: =IFERROR(Q11^2,"") -> 25
A12: Huddersfield | B12: =IFERROR((VLOOKUP($A12,'16-17'!$B:$L,6,FALSE)-VLOOKUP($A12,'16-17'!$B:$L,7,FALSE))/VLOOKUP($A12,'16-17'!$B:$L,2,FALSE),"") | C12: =IFERROR((VLOOKUP($A12,'17-18 First 5'!$B:$L,6,FALSE)-VLOOKUP($A12,'17-18 First 5'!$B:$L,7,FALSE))/VLOOKUP($A12,'17-18 First 5'!$B:$L,2,FALSE),"") -> 0.4 | D12: =IFERROR((VLOOKUP($A12,'17-18 First 10'!$B:$L,6,FALSE)-VLOOKUP($A12,'17-18 First 10'!$B:$L,7,FALSE))/VLOOKUP($A12,'17-18 First 10'!$B:$L,2,FALSE),"") -> -0.6 | E12: =IFERROR((VLOOKUP($A12,'17-18 First 15'!$B:$L,6,FALSE)-VLOOKUP($A12,'17-18 First 15'!$B:$L,7,FALSE))/VLOOKUP($A12,'17-18 First 15'!$B:$L,2,FALSE),"") -> -1.1333333 | F12: =IFERROR((VLOOKUP($A12,'17-18 First 20'!$B:$L,6,FALSE)-VLOOKUP($A12,'17-18 First 20'!$B:$L,7,FALSE))/VLOOKUP($A12,'17-18 First 20'!$B:$L,2,FALSE),"") -> -0.7 | G12: 16 | H12: =IFERROR(RANK(B12,$B$2:$B$21,0),"") | I12: =IFERROR(RANK(C12,$C$2:$C$21,0),"") -> 5 | J12: =IFERROR(RANK(D12,$D$2:$D$21,0),"") -> 15 | K12: =IFERROR(RANK(E12,$E$2:$E$21,0),"") -> 18 | L12: =IFERROR(RANK(F12,$F$2:$F$21,0),"") -> 16 | M12: =IFERROR(ABS(H12-$G12),"") | N12: =IFERROR(ABS(I12-$G12),"") -> 11 | O12: =IFERROR(ABS(J12-$G12),"") -> 1 | P12: =IFERROR(ABS(K12-$G12),"") -> 2 | Q12: =IFERROR(ABS(L12-$G12),"") -> 0 | R12: =IFERROR(M12^2,"") | S12: =IFERROR(N12^2,"") -> 121 | T12: =IFERROR(O12^2,"") -> 1 | U12: =IFERROR(P12^2,"") -> 4 | V12: =IFERROR(Q12^2,"") -> 0
A13: Brighton | B13: =IFERROR((VLOOKUP($A13,'16-17'!$B:$L,6,FALSE)-VLOOKUP($A13,'16-17'!$B:$L,7,FALSE))/VLOOKUP($A13,'16-17'!$B:$L,2,FALSE),"") | C13: =IFERROR((VLOOKUP($A13,'17-18 First 5'!$B:$L,6,FALSE)-VLOOKUP($A13,'17-18 First 5'!$B:$L,7,FALSE))/VLOOKUP($A13,'17-18 First 5'!$B:$L,2,FALSE),"") -> -0.6 | D13: =IFERROR((VLOOKUP($A13,'17-18 First 10'!$B:$L,6,FALSE)-VLOOKUP($A13,'17-18 First 10'!$B:$L,7,FALSE))/VLOOKUP($A13,'17-18 First 10'!$B:$L,2,FALSE),"") -> -0.1 | E13: =IFERROR((VLOOKUP($A13,'17-18 First 15'!$B:$L,6,FALSE)-VLOOKUP($A13,'17-18 First 15'!$B:$L,7,FALSE))/VLOOKUP($A13,'17-18 First 15'!$B:$L,2,FALSE),"") -> -0.33333333 | F13: =IFERROR((VLOOKUP($A13,'17-18 First 20'!$B:$L,6,FALSE)-VLOOKUP($A13,'17-18 First 20'!$B:$L,7,FALSE))/VLOOKUP($A13,'17-18 First 20'!$B:$L,2,FALSE),"") -> -0.5 | G13: 15 | H13: =IFERROR(RANK(B13,$B$2:$B$21,0),"") | I13: =IFERROR(RANK(C13,$C$2:$C$21,0),"") -> 15 | J13: =IFERROR(RANK(D13,$D$2:$D$21,0),"") -> 10 | K13: =IFERROR(RANK(E13,$E$2:$E$21,0),"") -> 12 | L13: =IFERROR(RANK(F13,$F$2:$F$21,0),"") -> 11 | M13: =IFERROR(ABS(H13-$G13),"") | N13: =IFERROR(ABS(I13-$G13),"") -> 0 | O13: =IFERROR(ABS(J13-$G13),"") -> 5 | P13: =IFERROR(ABS(K13-$G13),"") -> 3 | Q13: =IFERROR(ABS(L13-$G13),"") -> 4 | R13: =IFERROR(M13^2,"") | S13: =IFERROR(N13^2,"") -> 0 | T13: =IFERROR(O13^2,"") -> 25 | U13: =IFERROR(P13^2,"") -> 9 | V13: =IFERROR(Q13^2,"") -> 16
A14: Stoke | B14: =IFERROR((VLOOKUP($A14,'16-17'!$B:$L,6,FALSE)-VLOOKUP($A14,'16-17'!$B:$L,7,FALSE))/VLOOKUP($A14,'16-17'!$B:$L,2,FALSE),"") -> -0.39473684 | C14: =IFERROR((VLOOKUP($A14,'17-18 First 5'!$B:$L,6,FALSE)-VLOOKUP($A14,'17-18 First 5'!$B:$L,7,FALSE))/VLOOKUP($A14,'17-18 First 5'!$B:$L,2,FALSE),"") -> -0.2 | D14: =IFERROR((VLOOKUP($A14,'17-18 First 10'!$B:$L,6,FALSE)-VLOOKUP($A14,'17-18 First 10'!$B:$L,7,FALSE))/VLOOKUP($A14,'17-18 First 10'!$B:$L,2,FALSE),"") -> -0.9 | E14: =IFERROR((VLOOKUP($A14,'17-18 First 15'!$B:$L,6,FALSE)-VLOOKUP($A14,'17-18 First 15'!$B:$L,7,FALSE))/VLOOKUP($A14,'17-18 First 15'!$B:$L,2,FALSE),"") -> -0.8 | F14: =IFERROR((VLOOKUP($A14,'17-18 First 20'!$B:$L,6,FALSE)-VLOOKUP($A14,'17-18 First 20'!$B:$L,7,FALSE))/VLOOKUP($A14,'17-18 First 20'!$B:$L,2,FALSE),"") -> -0.9 | G14: 19 | H14: =IFERROR(RANK(B14,$B$2:$B$21,0),"") -> 12 | I14: =IFERROR(RANK(C14,$C$2:$C$21,0),"") -> 11 | J14: =IFERROR(RANK(D14,$D$2:$D$21,0),"") -> 17 | K14: =IFERROR(RANK(E14,$E$2:$E$21,0),"") -> 17 | L14: =IFERROR(RANK(F14,$F$2:$F$21,0),"") -> 19 | M14: =IFERROR(ABS(H14-$G14),"") -> 7 | N14: =IFERROR(ABS(I14-$G14),"") -> 8 | O14: =IFERROR(ABS(J14-$G14),"") -> 2 | P14: =IFERROR(ABS(K14-$G14),"") -> 2 | Q14: =IFERROR(ABS(L14-$G14),"") -> 0 | R14: =IFERROR(M14^2,"") -> 49 | S14: =IFERROR(N14^2,"") -> 64 | T14: =IFERROR(O14^2,"") -> 4 | U14: =IFERROR(P14^2,"") -> 4 | V14: =IFERROR(Q14^2,"") -> 0
A15: Southampton | B15: =IFERROR((VLOOKUP($A15,'16-17'!$B:$L,6,FALSE)-VLOOKUP($A15,'16-17'!$B:$L,7,FALSE))/VLOOKUP($A15,'16-17'!$B:$L,2,FALSE),"") -> -0.18421053 | C15: =IFERROR((VLOOKUP($A15,'17-18 First 5'!$B:$L,6,FALSE)-VLOOKUP($A15,'17-18 First 5'!$B:$L,7,FALSE))/VLOOKUP($A15,'17-18 First 5'!$B:$L,2,FALSE),"") -> 0 | D15: =IFERROR((VLOOKUP($A15,'17-18 First 10'!$B:$L,6,FALSE)-VLOOKUP($A15,'17-18 First 10'!$B:$L,7,FALSE))/VLOOKUP($A15,'17-18 First 10'!$B:$L,2,FALSE),"") -> -0.1 | E15: =IFERROR((VLOOKUP($A15,'17-18 First 15'!$B:$L,6,FALSE)-VLOOKUP($A15,'17-18 First 15'!$B:$L,7,FALSE))/VLOOKUP($A15,'17-18 First 15'!$B:$L,2,FALSE),"") -> -0.2 | F15: =IFERROR((VLOOKUP($A15,'17-18 First 20'!$B:$L,6,FALSE)-VLOOKUP($A15,'17-18 First 20'!$B:$L,7,FALSE))/VLOOKUP($A15,'17-18 First 20'!$B:$L,2,FALSE),"") -> -0.5 | G15: 17 | H15: =IFERROR(RANK(B15,$B$2:$B$21,0),"") -> 8 | I15: =IFERROR(RANK(C15,$C$2:$C$21,0),"") -> 8 | J15: =IFERROR(RANK(D15,$D$2:$D$21,0),"") -> 10 | K15: =IFERROR(RANK(E15,$E$2:$E$21,0),"") -> 10 | L15: =IFERROR(RANK(F15,$F$2:$F$21,0),"") -> 11 | M15: =IFERROR(ABS(H15-$G15),"") -> 9 | N15: =IFERROR(ABS(I15-$G15),"") -> 9 | O15: =IFERROR(ABS(J15-$G15),"") -> 7 | P15: =IFERROR(ABS(K15-$G15),"") -> 7 | Q15: =IFERROR(ABS(L15-$G15),"") -> 6 | R15: =IFERROR(M15^2,"") -> 81 | S15: =IFERROR(N15^2,"") -> 81 | T15: =IFERROR(O15^2,"") -> 49 | U15: =IFERROR(P15^2,"") -> 49 | V15: =IFERROR(Q15^2,"") -> 36
A16: Newcastle United | B16: =IFERROR((VLOOKUP($A16,'16-17'!$B:$L,6,FALSE)-VLOOKUP($A16,'16-17'!$B:$L,7,FALSE))/VLOOKUP($A16,'16-17'!$B:$L,2,FALSE),"") | C16: =IFERROR((VLOOKUP($A16,'17-18 First 5'!$B:$L,6,FALSE)-VLOOKUP($A16,'17-18 First 5'!$B:$L,7,FALSE))/VLOOKUP($A16,'17-18 First 5'!$B:$L,2,FALSE),"") -> 0.4 | D16: =IFERROR((VLOOKUP($A16,'17-18 First 10'!$B:$L,6,FALSE)-VLOOKUP($A16,'17-18 First 10'!$B:$L,7,FALSE))/VLOOKUP($A16,'17-18 First 10'!$B:$L,2,FALSE),"") -> 0.1 | E16: =IFERROR((VLOOKUP($A16,'17-18 First 15'!$B:$L,6,FALSE)-VLOOKUP($A16,'17-18 First 15'!$B:$L,7,FALSE))/VLOOKUP($A16,'17-18 First 15'!$B:$L,2,FALSE),"") -> -0.53333333 | F16: =IFERROR((VLOOKUP($A16,'17-18 First 20'!$B:$L,6,FALSE)-VLOOKUP($A16,'17-18 First 20'!$B:$L,7,FALSE))/VLOOKUP($A16,'17-18 First 20'!$B:$L,2,FALSE),"") -> -0.55 | G16: 10 | H16: =IFERROR(RANK(B16,$B$2:$B$21,0),"") | I16: =IFERROR(RANK(C16,$C$2:$C$21,0),"") -> 5 | J16: =IFERROR(RANK(D16,$D$2:$D$21,0),"") -> 6 | K16: =IFERROR(RANK(E16,$E$2:$E$21,0),"") -> 13 | L16: =IFERROR(RANK(F16,$F$2:$F$21,0),"") -> 13 | M16: =IFERROR(ABS(H16-$G16),"") | N16: =IFERROR(ABS(I16-$G16),"") -> 5 | O16: =IFERROR(ABS(J16-$G16),"") -> 4 | P16: =IFERROR(ABS(K16-$G16),"") -> 3 | Q16: =IFERROR(ABS(L16-$G16),"") -> 3 | R16: =IFERROR(M16^2,"") | S16: =IFERROR(N16^2,"") -> 25 | T16: =IFERROR(O16^2,"") -> 16 | U16: =IFERROR(P16^2,"") -> 9 | V16: =IFERROR(Q16^2,"") -> 9
A17: Crystal Palace | B17: =IFERROR((VLOOKUP($A17,'16-17'!$B:$L,6,FALSE)-VLOOKUP($A17,'16-17'!$B:$L,7,FALSE))/VLOOKUP($A17,'16-17'!$B:$L,2,FALSE),"") -> -0.34210526 | C17: =IFERROR((VLOOKUP($A17,'17-18 First 5'!$B:$L,6,FALSE)-VLOOKUP($A17,'17-18 First 5'!$B:$L,7,FALSE))/VLOOKUP($A17,'17-18 First 5'!$B:$L,2,FALSE),"") -> -1.6 | D17: =IFERROR((VLOOKUP($A17,'17-18 First 10'!$B:$L,6,FALSE)-VLOOKUP($A17,'17-18 First 10'!$B:$L,7,FALSE))/VLOOKUP($A17,'17-18 First 10'!$B:$L,2,FALSE),"") -> -1.7 | E17: =IFERROR((VLOOKUP($A17,'17-18 First 15'!$B:$L,6,FALSE)-VLOOKUP($A17,'17-18 First 15'!$B:$L,7,FALSE))/VLOOKUP($A17,'17-18 First 15'!$B:$L,2,FALSE),"") -> -1.1333333 | F17: =IFERROR((VLOOKUP($A17,'17-18 First 20'!$B:$L,6,FALSE)-VLOOKUP($A17,'17-18 First 20'!$B:$L,7,FALSE))/VLOOKUP($A17,'17-18 First 20'!$B:$L,2,FALSE),"") -> -0.7 | G17: 11 | H17: =IFERROR(RANK(B17,$B$2:$B$21,0),"") -> 11 | I17: =IFERROR(RANK(C17,$C$2:$C$21,0),"") -> 19 | J17: =IFERROR(RANK(D17,$D$2:$D$21,0),"") -> 20 | K17: =IFERROR(RANK(E17,$E$2:$E$21,0),"") -> 18 | L17: =IFERROR(RANK(F17,$F$2:$F$21,0),"") -> 16 | M17: =IFERROR(ABS(H17-$G17),"") -> 0 | N17: =IFERROR(ABS(I17-$G17),"") -> 8 | O17: =IFERROR(ABS(J17-$G17),"") -> 9 | P17: =IFERROR(ABS(K17-$G17),"") -> 7 | Q17: =IFERROR(ABS(L17-$G17),"") -> 5 | R17: =IFERROR(M17^2,"") -> 0 | S17: =IFERROR(N17^2,"") -> 64 | T17: =IFERROR(O17^2,"") -> 81 | U17: =IFERROR(P17^2,"") -> 49 | V17: =IFERROR(Q17^2,"") -> 25
... A21: Swansea | B21: =IFERROR((VLOOKUP($A21,'16-17'!$B:$L,6,FALSE)-VLOOKUP($A21,'16-17'!$B:$L,7,FALSE))/VLOOKUP($A21,'16-17'!$B:$L,2,FALSE),"") -> -0.65789474 | C21: =IFERROR((VLOOKUP($A21,'17-18 First 5'!$B:$L,6,FALSE)-VLOOKUP($A21,'17-18 First 5'!$B:$L,7,FALSE))/VLOOKUP($A21,'17-18 First 5'!$B:$L,2,FALSE),"") -> -0.6 | D21: =IFERROR((VLOOKUP($A21,'17-18 First 10'!$B:$L,6,FALSE)-VLOOKUP($A21,'17-18 First 10'!$B:$L,7,FALSE))/VLOOKUP($A21,'17-18 First 10'!$B:$L,2,FALSE),"") -> -0.5 | E21: =IFERROR((VLOOKUP($A21,'17-18 First 15'!$B:$L,6,FALSE)-VLOOKUP($A21,'17-18 First 15'!$B:$L,7,FALSE))/VLOOKUP($A21,'17-18 First 15'!$B:$L,2,FALSE),"") -> -0.66666667 | F21: =IFERROR((VLOOKUP($A21,'17-18 First 20'!$B:$L,6,FALSE)-VLOOKUP($A21,'17-18 First 20'!$B:$L,7,FALSE))/VLOOKUP($A21,'17-18 First 20'!$B:$L,2,FALSE),"") -> -1 | G21: 18 | H21: =IFERROR(RANK(B21,$B$2:$B$21,0),"") -> 16 | I21: =IFERROR(RANK(C21,$C$2:$C$21,0),"") -> 15 | J21: =IFERROR(RANK(D21,$D$2:$D$21,0),"") -> 14 | K21: =IFERROR(RANK(E21,$E$2:$E$21,0),"") -> 16 | L21: =IFERROR(RANK(F21,$F$2:$F$21,0),"") -> 20 | M21: =IFERROR(ABS(H21-$G21),"") -> 2 | N21: =IFERROR(ABS(I21-$G21),"") -> 3 | O21: =IFERROR(ABS(J21-$G21),"") -> 4 | P21: =IFERROR(ABS(K21-$G21),"") -> 2 | Q21: =IFERROR(ABS(L21-$G21),"") -> 2 | R21: =IFERROR(M21^2,"") -> 4 | S21: =IFERROR(N21^2,"") -> 9 | T21: =IFERROR(O21^2,"") -> 16 | U21: =IFERROR(P21^2,"") -> 4 | V21: =IFERROR(Q21^2,"") -> 4
